Workbook

Sheet Instrucciones
B2: SEGUIMIENTO DE CARGA Y DOLOR
B3: Cadete Masculino · Temporada 2026/2027 · 39 microciclos
B5: Qué se registra
B6: Percepción de esfuerzo (RPE) después de cada sesión, escala 0-10. Se pregunta al acabar, no durante.
B7: Dolor en rodilla, talón y espalda, escala 0-10, una vez por semana. Basta preguntarlo el lunes.
B8: Talla, cada dos meses, en la hoja Jugadores.
B9: Salto vertical (CMJ), cada dos o tres semanas, tres intentos el lunes. Se anota el mejor en la hoja Registro. Un descenso mantenido respecto a la media del jugador indica fatiga acumulada.
B10: Bienestar: sueño, fatiga, agujetas y ánimo, escala 1-5, los lunes. Se anota la suma.
B12: Hojas del libro
B13: Jugadores — Escribe aquí los nombres. Se propagan solos al resto de hojas. Debajo, las siete mediciones de talla y el crecimiento entre ellas.
B14: Registro — Es la única hoja donde se escriben datos de sesión. Una fila por jugador y semana. Rellena solo las celdas amarillas.
B15: Panel dolor — Mapa de calor del dolor máximo de cada jugador semana a semana. Se rellena solo.
... B30: Celdas amarillas: para rellenar. Celdas blancas o grises: calculadas, no tocar.

Sheet Jugadores
A1: PLANTILLA Y CONTROL DE CRECIMIENTO
A2: Escribe los nombres en la columna B. Las tallas van en centímetros.
A4: # | B4: Jugador | C4: Año nac. | D4: Puesto | E4: Talla 7 sep | F4: Talla 5 oct | G4: Talla 23 nov | H4: Talla 18 ene | I4: Talla 15 feb | J4: Talla 8 mar | K4: Talla 26 abr | L4: Máx. crecim. (cm) | M4: Aviso
A5: 1 | B5: Jugador 1 | L5: =IF(COUNT(E5:K5)<2,"",MAX(IFERROR(F5-E5,0),IFERROR(G5-F5,0),IFERROR(H5-G5,0),IFERROR(I5-H5,0),IFERROR(J5-I5,0),IFERROR(K5-J5,0))) | M5: =IF(L5="","",IF(L5>1.2,"Pico de crecimiento · mitad de contactos de pliometría","Normal"))
A6: 2 | B6: Jugador 2 | L6: =IF(COUNT(E6:K6)<2,"",MAX(IFERROR(F6-E6,0),IFERROR(G6-F6,0),IFERROR(H6-G6,0),IFERROR(I6-H6,0),IFERROR(J6-I6,0),IFERROR(K6-J6,0))) | M6: =IF(L6="","",IF(L6>1.2,"Pico de crecimiento · mitad de contactos de pliometría","Normal"))
A7: 3 | B7: Jugador 3 | L7: =IF(COUNT(E7:K7)<2,"",MAX(IFERROR(F7-E7,0),IFERROR(G7-F7,0),IFERROR(H7-G7,0),IFERROR(I7-H7,0),IFERROR(J7-I7,0),IFERROR(K7-J7,0))) | M7: =IF(L7="","",IF(L7>1.2,"Pico de crecimiento · mitad de contactos de pliometría","Normal"))
A8: 4 | B8: Jugador 4 | L8: =IF(COUNT(E8:K8)<2,"",MAX(IFERROR(F8-E8,0),IFERROR(G8-F8,0),IFERROR(H8-G8,0),IFERROR(I8-H8,0),IFERROR(J8-I8,0),IFERROR(K8-J8,0))) | M8: =IF(L8="","",IF(L8>1.2,"Pico de crecimiento · mitad de contactos de pliometría","Normal"))
A9: 5 | B9: Jugador 5 | L9: =IF(COUNT(E9:K9)<2,"",MAX(IFERROR(F9-E9,0),IFERROR(G9-F9,0),IFERROR(H9-G9,0),IFERROR(I9-H9,0),IFERROR(J9-I9,0),IFERROR(K9-J9,0))) | M9: =IF(L9="","",IF(L9>1.2,"Pico de crecimiento · mitad de contactos de pliometría","Normal"))
A10: 6 | B10: Jugador 6 | L10: =IF(COUNT(E10:K10)<2,"",MAX(IFERROR(F10-E10,0),IFERROR(G10-F10,0),IFERROR(H10-G10,0),IFERROR(I10-H10,0),IFERROR(J10-I10,0),IFERROR(K10-J10,0))) | M10: =IF(L10="","",IF(L10>1.2,"Pico de crecimiento · mitad de contactos de pliometría","Normal"))
A11: 7 | B11: Jugador 7 | L11: =IF(COUNT(E11:K11)<2,"",MAX(IFERROR(F11-E11,0),IFERROR(G11-F11,0),IFERROR(H11-G11,0),IFERROR(I11-H11,0),IFERROR(J11-I11,0),IFERROR(K11-J11,0))) | M11: =IF(L11="","",IF(L11>1.2,"Pico de crecimiento · mitad de contactos de pliometría","Normal"))
A12: 8 | B12: Jugador 8 | L12: =IF(COUNT(E12:K12)<2,"",MAX(IFERROR(F12-E12,0),IFERROR(G12-F12,0),IFERROR(H12-G12,0),IFERROR(I12-H12,0),IFERROR(J12-I12,0),IFERROR(K12-J12,0))) | M12: =IF(L12="","",IF(L12>1.2,"Pico de crecimiento · mitad de contactos de pliometría","Normal"))
A13: 9 | B13: Jugador 9 | L13: =IF(COUNT(E13:K13)<2,"",MAX(IFERROR(F13-E13,0),IFERROR(G13-F13,0),IFERROR(H13-G13,0),IFERROR(I13-H13,0),IFERROR(J13-I13,0),IFERROR(K13-J13,0))) | M13: =IF(L13="","",IF(L13>1.2,"Pico de crecimiento · mitad de contactos de pliometría","Normal"))
A14: 10 | B14: Jugador 10 | L14: =IF(COUNT(E14:K14)<2,"",MAX(IFERROR(F14-E14,0),IFERROR(G14-F14,0),IFERROR(H14-G14,0),IFERROR(I14-H14,0),IFERROR(J14-I14,0),IFERROR(K14-J14,0))) | M14: =IF(L14="","",IF(L14>1.2,"Pico de crecimiento · mitad de contactos de pliometría","Normal"))
A15: 11 | B15: Jugador 11 | L15: =IF(COUNT(E15:K15)<2,"",MAX(IFERROR(F15-E15,0),IFERROR(G15-F15,0),IFERROR(H15-G15,0),IFERROR(I15-H15,0),IFERROR(J15-I15,0),IFERROR(K15-J15,0))) | M15: =IF(L15="","",IF(L15>1.2,"Pico de crecimiento · mitad de contactos de pliometría","Normal"))
A16: 12 | B16: Jugador 12 | L16: =IF(COUNT(E16:K16)<2,"",MAX(IFERROR(F16-E16,0),IFERROR(G16-F16,0),IFERROR(H16-G16,0),IFERROR(I16-H16,0),IFERROR(J16-I16,0),IFERROR(K16-J16,0))) | M16: =IF(L16="","",IF(L16>1.2,"Pico de crecimiento · mitad de contactos de pliometría","Normal"))
... A18: 14 | B18: Jugador 14 | L18: =IF(COUNT(E18:K18)<2,"",MAX(IFERROR(F18-E18,0),IFERROR(G18-F18,0),IFERROR(H18-G18,0),IFERROR(I18-H18,0),IFERROR(J18-I18,0),IFERROR(K18-J18,0))) | M18: =IF(L18="","",IF(L18>1.2,"Pico de crecimiento · mitad de contactos de pliometría","Normal"))

Sheet Registro
A1: REGISTRO SEMANAL
A2: Rellena solo las celdas amarillas. Una fila por jugador y semana.
A4: Sem | B4: Lunes | C4: Meso | D4: Partido | E4: Carga plan. | F4: Jugador | G4: RPE L | H4: RPE X | I4: RPE V | J4: Carga sem. | K4: Dolor rodilla | L4: Dolor talón | M4: Dolor espalda | N4: Máx dolor | O4: Actuación | P4: CMJ (cm) | Q4: Bienestar (4-20)
A5: 1 | B5: 46272 | C5: M0 | D5: — | E5: 6 | F5: =Jugadores!$B$5 -> Jugador 1 | J5: =IF(COUNT(G5:I5)=0,"",G5*55+H5*50+I5*50) | N5: =IF(COUNT(K5:M5)=0,"",MAX(K5:M5)) | O5: =IF(N5="","",IF(N5>=7,"Sin pliometría ni velocidad. Solo isométricos, movilidad y tren superior. Valoración médica",IF(N5>=4,"Sin pliometría el lunes. Sentadilla española 5x45 s","Sesión normal")))
A6: 1 | B6: 46272 | C6: M0 | D6: — | E6: 6 | F6: =Jugadores!$B$6 -> Jugador 2 | J6: =IF(COUNT(G6:I6)=0,"",G6*55+H6*50+I6*50) | N6: =IF(COUNT(K6:M6)=0,"",MAX(K6:M6)) | O6: =IF(N6="","",IF(N6>=7,"Sin pliometría ni velocidad. Solo isométricos, movilidad y tren superior. Valoración médica",IF(N6>=4,"Sin pliometría el lunes. Sentadilla española 5x45 s","Sesión normal")))
A7: 1 | B7: 46272 | C7: M0 | D7: — | E7: 6 | F7: =Jugadores!$B$7 -> Jugador 3 | J7: =IF(COUNT(G7:I7)=0,"",G7*55+H7*50+I7*50) | N7: =IF(COUNT(K7:M7)=0,"",MAX(K7:M7)) | O7: =IF(N7="","",IF(N7>=7,"Sin pliometría ni velocidad. Solo isométricos, movilidad y tren superior. Valoración médica",IF(N7>=4,"Sin pliometría el lunes. Sentadilla española 5x45 s","Sesión normal")))
A8: 1 | B8: 46272 | C8: M0 | D8: — | E8: 6 | F8: =Jugadores!$B$8 -> Jugador 4 | J8: =IF(COUNT(G8:I8)=0,"",G8*55+H8*50+I8*50) | N8: =IF(COUNT(K8:M8)=0,"",MAX(K8:M8)) | O8: =IF(N8="","",IF(N8>=7,"Sin pliometría ni velocidad. Solo isométricos, movilidad y tren superior. Valoración médica",IF(N8>=4,"Sin pliometría el lunes. Sentadilla española 5x45 s","Sesión normal")))
A9: 1 | B9: 46272 | C9: M0 | D9: — | E9: 6 | F9: =Jugadores!$B$9 -> Jugador 5 | J9: =IF(COUNT(G9:I9)=0,"",G9*55+H9*50+I9*50) | N9: =IF(COUNT(K9:M9)=0,"",MAX(K9:M9)) | O9: =IF(N9="","",IF(N9>=7,"Sin pliometría ni velocidad. Solo isométricos, movilidad y tren superior. Valoración médica",IF(N9>=4,"Sin pliometría el lunes. Sentadilla española 5x45 s","Sesión normal")))
A10: 1 | B10: 46272 | C10: M0 | D10: — | E10: 6 | F10: =Jugadores!$B$10 -> Jugador 6 | J10: =IF(COUNT(G10:I10)=0,"",G10*55+H10*50+I10*50) | N10: =IF(COUNT(K10:M10)=0,"",MAX(K10:M10)) | O10: =IF(N10="","",IF(N10>=7,"Sin pliometría ni velocidad. Solo isométricos, movilidad y tren superior. Valoración médica",IF(N10>=4,"Sin pliometría el lunes. Sentadilla española 5x45 s","Sesión normal")))
A11: 1 | B11: 46272 | C11: M0 | D11: — | E11: 6 | F11: =Jugadores!$B$11 -> Jugador 7 | J11: =IF(COUNT(G11:I11)=0,"",G11*55+H11*50+I11*50) | N11: =IF(COUNT(K11:M11)=0,"",MAX(K11:M11)) | O11: =IF(N11="","",IF(N11>=7,"Sin pliometría ni velocidad. Solo isométricos, movilidad y tren superior. Valoración médica",IF(N11>=4,"Sin pliometría el lunes. Sentadilla española 5x45 s","Sesión normal")))
A12: 1 | B12: 46272 | C12: M0 | D12: — | E12: 6 | F12: =Jugadores!$B$12 -> Jugador 8 | J12: =IF(COUNT(G12:I12)=0,"",G12*55+H12*50+I12*50) | N12: =IF(COUNT(K12:M12)=0,"",MAX(K12:M12)) | O12: =IF(N12="","",IF(N12>=7,"Sin pliometría ni velocidad. Solo isométricos, movilidad y tren superior. Valoración médica",IF(N12>=4,"Sin pliometría el lunes. Sentadilla española 5x45 s","Sesión normal")))
A13: 1 | B13: 46272 | C13: M0 | D13: — | E13: 6 | F13: =Jugadores!$B$13 -> Jugador 9 | J13: =IF(COUNT(G13:I13)=0,"",G13*55+H13*50+I13*50) | N13: =IF(COUNT(K13:M13)=0,"",MAX(K13:M13)) | O13: =IF(N13="","",IF(N13>=7,"Sin pliometría ni velocidad. Solo isométricos, movilidad y tren superior. Valoración médica",IF(N13>=4,"Sin pliometría el lunes. Sentadilla española 5x45 s","Sesión normal")))
A14: 1 | B14: 46272 | C14: M0 | D14: — | E14: 6 | F14: =Jugadores!$B$14 -> Jugador 10 | J14: =IF(COUNT(G14:I14)=0,"",G14*55+H14*50+I14*50) | N14: =IF(COUNT(K14:M14)=0,"",MAX(K14:M14)) | O14: =IF(N14="","",IF(N14>=7,"Sin pliometría ni velocidad. Solo isométricos, movilidad y tren superior. Valoración médica",IF(N14>=4,"Sin pliometría el lunes. Sentadilla española 5x45 s","Sesión normal")))
A15: 1 | B15: 46272 | C15: M0 | D15: — | E15: 6 | F15: =Jugadores!$B$15 -> Jugador 11 | J15: =IF(COUNT(G15:I15)=0,"",G15*55+H15*50+I15*50) | N15: =IF(COUNT(K15:M15)=0,"",MAX(K15:M15)) | O15: =IF(N15="","",IF(N15>=7,"Sin pliometría ni velocidad. Solo isométricos, movilidad y tren superior. Valoración médica",IF(N15>=4,"Sin pliometría el lunes. Sentadilla española 5x45 s","Sesión normal")))
A16: 1 | B16: 46272 | C16: M0 | D16: — | E16: 6 | F16: =Jugadores!$B$16 -> Jugador 12 | J16: =IF(COUNT(G16:I16)=0,"",G16*55+H16*50+I16*50) | N16: =IF(COUNT(K16:M16)=0,"",MAX(K16:M16)) | O16: =IF(N16="","",IF(N16>=7,"Sin pliometría ni velocidad. Solo isométricos, movilidad y tren superior. Valoración médica",IF(N16>=4,"Sin pliometría el lunes. Sentadilla española 5x45 s","Sesión normal")))
A17: 1 | B17: 46272 | C17: M0 | D17: — | E17: 6 | F17: =Jugadores!$B$17 -> Jugador 13 | J17: =IF(COUNT(G17:I17)=0,"",G17*55+H17*50+I17*50) | N17: =IF(COUNT(K17:M17)=0,"",MAX(K17:M17)) | O17: =IF(N17="","",IF(N17>=7,"Sin pliometría ni velocidad. Solo isométricos, movilidad y tren superior. Valoración médica",IF(N17>=4,"Sin pliometría el lunes. Sentadilla española 5x45 s","Sesión normal")))
A18: 1 | B18: 46272 | C18: M0 | D18: — | E18: 6 | F18: =Jugadores!$B$18 -> Jugador 14 | J18: =IF(COUNT(G18:I18)=0,"",G18*55+H18*50+I18*50) | N18: =IF(COUNT(K18:M18)=0,"",MAX(K18:M18)) | O18: =IF(N18="","",IF(N18>=7,"Sin pliometría ni velocidad. Solo isométricos, movilidad y tren superior. Valoración médica",IF(N18>=4,"Sin pliometría el lunes. Sentadilla española 5x45 s","Sesión normal")))
A19: 2 | B19: 46279 | C19: M0 | D19: — | E19: 8 | F19: =Jugadores!$B$5 -> Jugador 1 | J19: =IF(COUNT(G19:I19)=0,"",G19*55+H19*50+I19*50) | N19: =IF(COUNT(K19:M19)=0,"",MAX(K19:M19)) | O19: =IF(N19="","",IF(N19>=7,"Sin pliometría ni velocidad. Solo isométricos, movilidad y tren superior. Valoración médica",IF(N19>=4,"Sin pliometría el lunes. Sentadilla española 5x45 s","Sesión normal")))
A20: 2 | B20: 46279 | C20: M0 | D20: — | E20: 8 | F20: =Jugadores!$B$6 -> Jugador 2 | J20: =IF(COUNT(G20:I20)=0,"",G20*55+H20*50+I20*50) | N20: =IF(COUNT(K20:M20)=0,"",MAX(K20:M20)) | O20: =IF(N20="","",IF(N20>=7,"Sin pliometría ni velocidad. Solo isométricos, movilidad y tren superior. Valoración médica",IF(N20>=4,"Sin pliometría el lunes. Sentadilla española 5x45 s","Sesión normal")))
A21: 2 | B21: 46279 | C21: M0 | D21: — | E21: 8 | F21: =Jugadores!$B$7 -> Jugador 3 | J21: =IF(COUNT(G21:I21)=0,"",G21*55+H21*50+I21*50) | N21: =IF(COUNT(K21:M21)=0,"",MAX(K21:M21)) | O21: =IF(N21="","",IF(N21>=7,"Sin pliometría ni velocidad. Solo isométricos, movilidad y tren superior. Valoración médica",IF(N21>=4,"Sin pliometría el lunes. Sentadilla española 5x45 s","Sesión normal")))
A22: 2 | B22: 46279 | C22: M0 | D22: — | E22: 8 | F22: =Jugadores!$B$8 -> Jugador 4 | J22: =IF(COUNT(G22:I22)=0,"",G22*55+H22*50+I22*50) | N22: =IF(COUNT(K22:M22)=0,"",MAX(K22:M22)) | O22: =IF(N22="","",IF(N22>=7,"Sin pliometría ni velocidad. Solo isométricos, movilidad y tren superior. Valoración médica",IF(N22>=4,"Sin pliometría el lunes. Sentadilla española 5x45 s","Sesión normal")))
A23: 2 | B23: 46279 | C23: M0 | D23: — | E23: 8 | F23: =Jugadores!$B$9 -> Jugador 5 | J23: =IF(COUNT(G23:I23)=0,"",G23*55+H23*50+I23*50) | N23: =IF(COUNT(K23:M23)=0,"",MAX(K23:M23)) | O23: =IF(N23="","",IF(N23>=7,"Sin pliometría ni velocidad. Solo isométricos, movilidad y tren superior. Valoración médica",IF(N23>=4,"Sin pliometría el lunes. Sentadilla española 5x45 s","Sesión normal")))
A24: 2 | B24: 46279 | C24: M0 | D24: — | E24: 8 | F24: =Jugadores!$B$10 -> Jugador 6 | J24: =IF(COUNT(G24:I24)=0,"",G24*55+H24*50+I24*50) | N24: =IF(COUNT(K24:M24)=0,"",MAX(K24:M24)) | O24: =IF(N24="","",IF(N24>=7,"Sin pliometría ni velocidad. Solo isométricos, movilidad y tren superior. Valoración médica",IF(N24>=4,"Sin pliometría el lunes. Sentadilla española 5x45 s","Sesión normal")))
A25: 2 | B25: 46279 | C25: M0 | D25: — | E25: 8 | F25: =Jugadores!$B$11 -> Jugador 7 | J25: =IF(COUNT(G25:I25)=0,"",G25*55+H25*50+I25*50) | N25: =IF(COUNT(K25:M25)=0,"",MAX(K25:M25)) | O25: =IF(N25="","",IF(N25>=7,"Sin pliometría ni velocidad. Solo isométricos, movilidad y tren superior. Valoración médica",IF(N25>=4,"Sin pliometría el lunes. Sentadilla española 5x45 s","Sesión normal")))
A26: 2 | B26: 46279 | C26: M0 | D26: — | E26: 8 | F26: =Jugadores!$B$12 -> Jugador 8 | J26: =IF(COUNT(G26:I26)=0,"",G26*55+H26*50+I26*50) | N26: =IF(COUNT(K26:M26)=0,"",MAX(K26:M26)) | O26: =IF(N26="","",IF(N26>=7,"Sin pliometría ni velocidad. Solo isométricos, movilidad y tren superior. Valoración médica",IF(N26>=4,"Sin pliometría el lunes. Sentadilla española 5x45 s","Sesión normal")))
A27: 2 | B27: 46279 | C27: M0 | D27: — | E27: 8 | F27: =Jugadores!$B$13 -> Jugador 9 | J27: =IF(COUNT(G27:I27)=0,"",G27*55+H27*50+I27*50) | N27: =IF(COUNT(K27:M27)=0,"",MAX(K27:M27)) | O27: =IF(N27="","",IF(N27>=7,"Sin pliometría ni velocidad. Solo isométricos, movilidad y tren superior. Valoración médica",IF(N27>=4,"Sin pliometría el lunes. Sentadilla española 5x45 s","Sesión normal")))
A28: 2 | B28: 46279 | C28: M0 | D28: — | E28: 8 | F28: =Jugadores!$B$14 -> Jugador 10 | J28: =IF(COUNT(G28:I28)=0,"",G28*55+H28*50+I28*50) | N28: =IF(COUNT(K28:M28)=0,"",MAX(K28:M28)) | O28: =IF(N28="","",IF(N28>=7,"Sin pliometría ni velocidad. Solo isométricos, movilidad y tren superior. Valoración médica",IF(N28>=4,"Sin pliometría el lunes. Sentadilla española 5x45 s","Sesión normal")))
A29: 2 | B29: 46279 | C29: M0 | D29: — | E29: 8 | F29: =Jugadores!$B$15 -> Jugador 11 | J29: =IF(COUNT(G29:I29)=0,"",G29*55+H29*50+I29*50) | N29: =IF(COUNT(K29:M29)=0,"",MAX(K29:M29)) | O29: =IF(N29="","",IF(N29>=7,"Sin pliometría ni velocidad. Solo isométricos, movilidad y tren superior. Valoración médica",IF(N29>=4,"Sin pliometría el lunes. Sentadilla española 5x45 s","Sesión normal")))
A30: 2 | B30: 46279 | C30: M0 | D30: — | E30: 8 | F30: =Jugadores!$B$16 -> Jugador 12 | J30: =IF(COUNT(G30:I30)=0,"",G30*55+H30*50+I30*50) | N30: =IF(COUNT(K30:M30)=0,"",MAX(K30:M30)) | O30: =IF(N30="","",IF(N30>=7,"Sin pliometría ni velocidad. Solo isométricos, movilidad y tren superior. Valoración médica",IF(N30>=4,"Sin pliometría el lunes. Sentadilla española 5x45 s","Sesión normal")))
A31: 2 | B31: 46279 | C31: M0 | D31: — | E31: 8 | F31: =Jugadores!$B$17 -> Jugador 13 | J31: =IF(COUNT(G31:I31)=0,"",G31*55+H31*50+I31*50) | N31: =IF(COUNT(K31:M31)=0,"",MAX(K31:M31)) | O31: =IF(N31="","",IF(N31>=7,"Sin pliometría ni velocidad. Solo isométricos, movilidad y tren superior. Valoración médica",IF(N31>=4,"Sin pliometría el lunes. Sentadilla española 5x45 s","Sesión normal")))
A32: 2 | B32: 46279 | C32: M0 | D32: — | E32: 8 | F32: =Jugadores!$B$18 -> Jugador 14 | J32: =IF(COUNT(G32:I32)=0,"",G32*55+H32*50+I32*50) | N32: =IF(COUNT(K32:M32)=0,"",MAX(K32:M32)) | O32: =IF(N32="","",IF(N32>=7,"Sin pliometría ni velocidad. Solo isométricos, movilidad y tren superior. Valoración médica",IF(N32>=4,"Sin pliometría el lunes. Sentadilla española 5x45 s","Sesión normal")))
A33: 3 | B33: 46286 | C33: M0 | D33: Amist. | E33: 9 | F33: =Jugadores!$B$5 -> Jugador 1 | J33: =IF(COUNT(G33:I33)=0,"",G33*55+H33*50+I33*50) | N33: =IF(COUNT(K33:M33)=0,"",MAX(K33:M33)) | O33: =IF(N33="","",IF(N33>=7,"Sin pliometría ni velocidad. Solo isométricos, movilidad y tren superior. Valoración médica",IF(N33>=4,"Sin pliometría el lunes. Sentadilla española 5x45 s","Sesión normal")))
A34: 3 | B34: 46286 | C34: M0 | D34: Amist. | E34: 9 | F34: =Jugadores!$B$6 -> Jugador 2 | J34: =IF(COUNT(G34:I34)=0,"",G34*55+H34*50+I34*50) | N34: =IF(COUNT(K34:M34)=0,"",MAX(K34:M34)) | O34: =IF(N34="","",IF(N34>=7,"Sin pliometría ni velocidad. Solo isométricos, movilidad y tren superior. Valoración médica",IF(N34>=4,"Sin pliometría el lunes. Sentadilla española 5x45 s","Sesión normal")))
A35: 3 | B35: 46286 | C35: M0 | D35: Amist. | E35: 9 | F35: =Jugadores!$B$7 -> Jugador 3 | J35: =IF(COUNT(G35:I35)=0,"",G35*55+H35*50+I35*50) | N35: =IF(COUNT(K35:M35)=0,"",MAX(K35:M35)) | O35: =IF(N35="","",IF(N35>=7,"Sin pliometría ni velocidad. Solo isométricos, movilidad y tren superior. Valoración médica",IF(N35>=4,"Sin pliometría el lunes. Sentadilla española 5x45 s","Sesión normal")))
A36: 3 | B36: 46286 | C36: M0 | D36: Amist. | E36: 9 | F36: =Jugadores!$B$8 -> Jugador 4 | J36: =IF(COUNT(G36:I36)=0,"",G36*55+H36*50+I36*50) | N36: =IF(COUNT(K36:M36)=0,"",MAX(K36:M36)) | O36: =IF(N36="","",IF(N36>=7,"Sin pliometría ni velocidad. Solo isométricos, movilidad y tren superior. Valoración médica",IF(N36>=4,"Sin pliometría el lunes. Sentadilla española 5x45 s","Sesión normal")))
A37: 3 | B37: 46286 | C37: M0 | D37: Amist. | E37: 9 | F37: =Jugadores!$B$9 -> Jugador 5 | J37: =IF(COUNT(G37:I37)=0,"",G37*55+H37*50+I37*50) | N37: =IF(COUNT(K37:M37)=0,"",MAX(K37:M37)) | O37: =IF(N37="","",IF(N37>=7,"Sin pliometría ni velocidad. Solo isométricos, movilidad y tren superior. Valoración médica",IF(N37>=4,"Sin pliometría el lunes. Sentadilla española 5x45 s","Sesión normal")))
A38: 3 | B38: 46286 | C38: M0 | D38: Amist. | E38: 9 | F38: =Jugadores!$B$10 -> Jugador 6 | J38: =IF(COUNT(G38:I38)=0,"",G38*55+H38*50+I38*50) | N38: =IF(COUNT(K38:M38)=0,"",MAX(K38:M38)) | O38: =IF(N38="","",IF(N38>=7,"Sin pliometría ni velocidad. Solo isométricos, movilidad y tren superior. Valoración médica",IF(N38>=4,"Sin pliometría el lunes. Sentadilla española 5x45 s","Sesión normal")))
A39: 3 | B39: 46286 | C39: M0 | D39: Amist. | E39: 9 | F39: =Jugadores!$B$11 -> Jugador 7 | J39: =IF(COUNT(G39:I39)=0,"",G39*55+H39*50+I39*50) | N39: =IF(COUNT(K39:M39)=0,"",MAX(K39:M39)) | O39: =IF(N39="","",IF(N39>=7,"Sin pliometría ni velocidad. Solo isométricos, movilidad y tren superior. Valoración médica",IF(N39>=4,"Sin pliometría el lunes. Sentadilla española 5x45 s","Sesión normal")))
A40: 3 | B40: 46286 | C40: M0 | D40: Amist. | E40: 9 | F40: =Jugadores!$B$12 -> Jugador 8 | J40: =IF(COUNT(G40:I40)=0,"",G40*55+H40*50+I40*50) | N40: =IF(COUNT(K40:M40)=0,"",MAX(K40:M40)) | O40: =IF(N40="","",IF(N40>=7,"Sin pliometría ni velocidad. Solo isométricos, movilidad y tren superior. Valoración médica",IF(N40>=4,"Sin pliometría el lunes. Sentadilla española 5x45 s","Sesión normal")))
A41: 3 | B41: 46286 | C41: M0 | D41: Amist. | E41: 9 | F41: =Jugadores!$B$13 -> Jugador 9 | J41: =IF(COUNT(G41:I41)=0,"",G41*55+H41*50+I41*50) | N41: =IF(COUNT(K41:M41)=0,"",MAX(K41:M41)) | O41: =IF(N41="","",IF(N41>=7,"Sin pliometría ni velocidad. Solo isométricos, movilidad y tren superior. Valoración médica",IF(N41>=4,"Sin pliometría el lunes. Sentadilla española 5x45 s","Sesión normal")))
...

Sheet Panel dolor
A1: MAPA DE DOLOR · Valor máximo semanal de rodilla, talón y espalda
A2: Se rellena solo a partir de la hoja Registro.
A3: Semana | B3: 1 | C3: 2 | D3: 3 | E3: 4 | F3: 5 | G3: 6 | H3: 7 | I3: 8 | J3: 9 | K3: 10 | L3: 11 | M3: 12 | N3: 13 | O3: 14 | P3: 15 | Q3: 16 | R3: 17 | S3: 18 | T3: 19 | U3: 20 | V3: 21 | W3: 22 | X3: 23 | Y3: 24 | Z3: 25 | AA3: 26 | AB3: 27 | AC3: 28 | AD3: 29 | AE3: 30 | AF3: 31 | AG3: 32 | AH3: 33 | AI3: 34 | AJ3: 35 | AK3: 36 | AL3: 37 | AM3: 38 | AN3: 39
A4: Jugador | B4: M0 | C4: M0 | D4: M0 | E4: M0 | F4: M1 | G4: M1 | H4: M1 | I4: M1 | J4: M1 | K4: M1 | L4: M1 | M4: M1 | N4: M2 | O4: M2 | P4: M2 | Q4: M3 | R4: M3 | S4: M3 | T4: M3 | U4: M4 | V4: M4 | W4: M4 | X4: M4 | Y4: M4 | Z4: M4 | AA4: M5 | AB4: M5 | AC4: M6 | AD4: M6 | AE4: M6 | AF4: M7 | AG4: M7 | AH4: M7 | AI4: M8 | AJ4: M8 | AK4: M9 | AL4: M9 | AM4: M9 | AN4: M9
A5: =Jugadores!$B$5 -> Jugador 1 | B5: =IF(SUMIFS(Registro!$N:$N,Registro!$A:$A,B$3,Registro!$F:$F,$A5)=0,"",SUMIFS(Registro!$N:$N,Registro!$A:$A,B$3,Registro!$F:$F,$A5)) | C5: =IF(SUMIFS(Registro!$N:$N,Registro!$A:$A,C$3,Registro!$F:$F,$A5)=0,"",SUMIFS(Registro!$N:$N,Registro!$A:$A,C$3,Registro!$F:$F,$A5)) | D5: =IF(SUMIFS(Registro!$N:$N,Registro!$A:$A,D$3,Registro!$F:$F,$A5)=0,"",SUMIFS(Registro!$N:$N,Registro!$A:$A,D$3,Registro!$F:$F,$A5)) | E5: =IF(SUMIFS(Registro!$N:$N,Registro!$A:$A,E$3,Registro!$F:$F,$A5)=0,"",SUMIFS(Registro!$N:$N,Registro!$A:$A,E$3,Registro!$F:$F,$A5)) | F5: =IF(SUMIFS(Registro!$N:$N,Registro!$A:$A,F$3,Registro!$F:$F,$A5)=0,"",SUMIFS(Registro!$N:$N,Registro!$A:$A,F$3,Registro!$F:$F,$A5)) | G5: =IF(SUMIFS(Registro!$N:$N,Registro!$A:$A,G$3,Registro!$F:$F,$A5)=0,"",SUMIFS(Registro!$N:$N,Registro!$A:$A,G$3,Registro!$F:$F,$A5)) | H5: =IF(SUMIFS(Registro!$N:$N,Registro!$A:$A,H$3,Registro!$F:$F,$A5)=0,"",SUMIFS(Registro!$N:$N,Registro!$A:$A,H$3,Registro!$F:$F,$A5)) | I5: =IF(SUMIFS(Registro!$N:$N,Registro!$A:$A,I$3,Registro!$F:$F,$A5)=0,"",SUMIFS(Registro!$N:$N,Registro!$A:$A,I$3,Registro!$F:$F,$A5)) | ... AN5: =IF(SUMIFS(Registro!$N:$N,Registro!$A:$A,AN$3,Registro!$F:$F,$A5)=0,"",SUMIFS(Registro!$N:$N,Registro!$A:$A,AN$3,Registro!$F:$F,$A5))
A6: =Jugadores!$B$6 -> Jugador 2 | B6: =IF(SUMIFS(Registro!$N:$N,Registro!$A:$A,B$3,Registro!$F:$F,$A6)=0,"",SUMIFS(Registro!$N:$N,Registro!$A:$A,B$3,Registro!$F:$F,$A6)) | C6: =IF(SUMIFS(Registro!$N:$N,Registro!$A:$A,C$3,Registro!$F:$F,$A6)=0,"",SUMIFS(Registro!$N:$N,Registro!$A:$A,C$3,Registro!$F:$F,$A6)) | D6: =IF(SUMIFS(Registro!$N:$N,Registro!$A:$A,D$3,Registro!$F:$F,$A6)=0,"",SUMIFS(Registro!$N:$N,Registro!$A:$A,D$3,Registro!$F:$F,$A6)) | E6: =IF(SUMIFS(Registro!$N:$N,Registro!$A:$A,E$3,Registro!$F:$F,$A6)=0,"",SUMIFS(Registro!$N:$N,Registro!$A:$A,E$3,Registro!$F:$F,$A6)) | F6: =IF(SUMIFS(Registro!$N:$N,Registro!$A:$A,F$3,Registro!$F:$F,$A6)=0,"",SUMIFS(Registro!$N:$N,Registro!$A:$A,F$3,Registro!$F:$F,$A6)) | G6: =IF(SUMIFS(Registro!$N:$N,Registro!$A:$A,G$3,Registro!$F:$F,$A6)=0,"",SUMIFS(Registro!$N:$N,Registro!$A:$A,G$3,Registro!$F:$F,$A6)) | H6: =IF(SUMIFS(Registro!$N:$N,Registro!$A:$A,H$3,Registro!$F:$F,$A6)=0,"",SUMIFS(Registro!$N:$N,Registro!$A:$A,H$3,Registro!$F:$F,$A6)) | I6: =IF(SUMIFS(Registro!$N:$N,Registro!$A:$A,I$3,Registro!$F:$F,$A6)=0,"",SUMIFS(Registro!$N:$N,Registro!$A:$A,I$3,Registro!$F:$F,$A6)) | ... AN6: =IF(SUMIFS(Registro!$N:$N,Registro!$A:$A,AN$3,Registro!$F:$F,$A6)=0,"",SUMIFS(Registro!$N:$N,Registro!$A:$A,AN$3,Registro!$F:$F,$A6))
A7: =Jugadores!$B$7 -> Jugador 3 | B7: =IF(SUMIFS(Registro!$N:$N,Registro!$A:$A,B$3,Registro!$F:$F,$A7)=0,"",SUMIFS(Registro!$N:$N,Registro!$A:$A,B$3,Registro!$F:$F,$A7)) | C7: =IF(SUMIFS(Registro!$N:$N,Registro!$A:$A,C$3,Registro!$F:$F,$A7)=0,"",SUMIFS(Registro!$N:$N,Registro!$A:$A,C$3,Registro!$F:$F,$A7)) | D7: =IF(SUMIFS(Registro!$N:$N,Registro!$A:$A,D$3,Registro!$F:$F,$A7)=0,"",SUMIFS(Registro!$N:$N,Registro!$A:$A,D$3,Registro!$F:$F,$A7)) | E7: =IF(SUMIFS(Registro!$N:$N,Registro!$A:$A,E$3,Registro!$F:$F,$A7)=0,"",SUMIFS(Registro!$N:$N,Registro!$A:$A,E$3,Registro!$F:$F,$A7)) | F7: =IF(SUMIFS(Registro!$N:$N,Registro!$A:$A,F$3,Registro!$F:$F,$A7)=0,"",SUMIFS(Registro!$N:$N,Registro!$A:$A,F$3,Registro!$F:$F,$A7)) | G7: =IF(SUMIFS(Registro!$N:$N,Registro!$A:$A,G$3,Registro!$F:$F,$A7)=0,"",SUMIFS(Registro!$N:$N,Registro!$A:$A,G$3,Registro!$F:$F,$A7)) | H7: =IF(SUMIFS(Registro!$N:$N,Registro!$A:$A,H$3,Registro!$F:$F,$A7)=0,"",SUMIFS(Registro!$N:$N,Registro!$A:$A,H$3,Registro!$F:$F,$A7)) | I7: =IF(SUMIFS(Registro!$N:$N,Registro!$A:$A,I$3,Registro!$F:$F,$A7)=0,"",SUMIFS(Registro!$N:$N,Registro!$A:$A,I$3,Registro!$F:$F,$A7)) | ... AN7: =IF(SUMIFS(Registro!$N:$N,Registro!$A:$A,AN$3,Registro!$F:$F,$A7)=0,"",SUMIFS(Registro!$N:$N,Registro!$A:$A,AN$3,Registro!$F:$F,$A7))
A8: =Jugadores!$B$8 -> Jugador 4 | B8: =IF(SUMIFS(Registro!$N:$N,Registro!$A:$A,B$3,Registro!$F:$F,$A8)=0,"",SUMIFS(Registro!$N:$N,Registro!$A:$A,B$3,Registro!$F:$F,$A8)) | C8: =IF(SUMIFS(Registro!$N:$N,Registro!$A:$A,C$3,Registro!$F:$F,$A8)=0,"",SUMIFS(Registro!$N:$N,Registro!$A:$A,C$3,Registro!$F:$F,$A8)) | D8: =IF(SUMIFS(Registro!$N:$N,Registro!$A:$A,D$3,Registro!$F:$F,$A8)=0,"",SUMIFS(Registro!$N:$N,Registro!$A:$A,D$3,Registro!$F:$F,$A8)) | E8: =IF(SUMIFS(Registro!$N:$N,Registro!$A:$A,E$3,Registro!$F:$F,$A8)=0,"",SUMIFS(Registro!$N:$N,Registro!$A:$A,E$3,Registro!$F:$F,$A8)) | F8: =IF(SUMIFS(Registro!$N:$N,Registro!$A:$A,F$3,Registro!$F:$F,$A8)=0,"",SUMIFS(Registro!$N:$N,Registro!$A:$A,F$3,Registro!$F:$F,$A8)) | G8: =IF(SUMIFS(Registro!$N:$N,Registro!$A:$A,G$3,Registro!$F:$F,$A8)=0,"",SUMIFS(Registro!$N:$N,Registro!$A:$A,G$3,Registro!$F:$F,$A8)) | H8: =IF(SUMIFS(Registro!$N:$N,Registro!$A:$A,H$3,Registro!$F:$F,$A8)=0,"",SUMIFS(Registro!$N:$N,Registro!$A:$A,H$3,Registro!$F:$F,$A8)) | I8: =IF(SUMIFS(Registro!$N:$N,Registro!$A:$A,I$3,Registro!$F:$F,$A8)=0,"",SUMIFS(Registro!$N:$N,Registro!$A:$A,I$3,Registro!$F:$F,$A8)) | ... AN8: =IF(SUMIFS(Registro!$N:$N,Registro!$A:$A,AN$3,Registro!$F:$F,$A8)=0,"",SUMIFS(Registro!$N:$N,Registro!$A:$A,AN$3,Registro!$F:$F,$A8))
A9: =Jugadores!$B$9 -> Jugador 5 | B9: =IF(SUMIFS(Registro!$N:$N,Registro!$A:$A,B$3,Registro!$F:$F,$A9)=0,"",SUMIFS(Registro!$N:$N,Registro!$A:$A,B$3,Registro!$F:$F,$A9)) | C9: =IF(SUMIFS(Registro!$N:$N,Registro!$A:$A,C$3,Registro!$F:$F,$A9)=0,"",SUMIFS(Registro!$N:$N,Registro!$A:$A,C$3,Registro!$F:$F,$A9)) | D9: =IF(SUMIFS(Registro!$N:$N,Registro!$A:$A,D$3,Registro!$F:$F,$A9)=0,"",SUMIFS(Registro!$N:$N,Registro!$A:$A,D$3,Registro!$F:$F,$A9)) | E9: =IF(SUMIFS(Registro!$N:$N,Registro!$A:$A,E$3,Registro!$F:$F,$A9)=0,"",SUMIFS(Registro!$N:$N,Registro!$A:$A,E$3,Registro!$F:$F,$A9)) | F9: =IF(SUMIFS(Registro!$N:$N,Registro!$A:$A,F$3,Registro!$F:$F,$A9)=0,"",SUMIFS(Registro!$N:$N,Registro!$A:$A,F$3,Registro!$F:$F,$A9)) | G9: =IF(SUMIFS(Registro!$N:$N,Registro!$A:$A,G$3,Registro!$F:$F,$A9)=0,"",SUMIFS(Registro!$N:$N,Registro!$A:$A,G$3,Registro!$F:$F,$A9)) | H9: =IF(SUMIFS(Registro!$N:$N,Registro!$A:$A,H$3,Registro!$F:$F,$A9)=0,"",SUMIFS(Registro!$N:$N,Registro!$A:$A,H$3,Registro!$F:$F,$A9)) | I9: =IF(SUMIFS(Registro!$N:$N,Registro!$A:$A,I$3,Registro!$F:$F,$A9)=0,"",SUMIFS(Registro!$N:$N,Registro!$A:$A,I$3,Registro!$F:$F,$A9)) | ... AN9: =IF(SUMIFS(Registro!$N:$N,Registro!$A:$A,AN$3,Registro!$F:$F,$A9)=0,"",SUMIFS(Registro!$N:$N,Registro!$A:$A,AN$3,Registro!$F:$F,$A9))
A10: =Jugadores!$B$10 -> Jugador 6 | B10: =IF(SUMIFS(Registro!$N:$N,Registro!$A:$A,B$3,Registro!$F:$F,$A10)=0,"",SUMIFS(Registro!$N:$N,Registro!$A:$A,B$3,Registro!$F:$F,$A10)) | C10: =IF(SUMIFS(Registro!$N:$N,Registro!$A:$A,C$3,Registro!$F:$F,$A10)=0,"",SUMIFS(Registro!$N:$N,Registro!$A:$A,C$3,Registro!$F:$F,$A10)) | D10: =IF(SUMIFS(Registro!$N:$N,Registro!$A:$A,D$3,Registro!$F:$F,$A10)=0,"",SUMIFS(Registro!$N:$N,Registro!$A:$A,D$3,Registro!$F:$F,$A10)) | E10: =IF(SUMIFS(Registro!$N:$N,Registro!$A:$A,E$3,Registro!$F:$F,$A10)=0,"",SUMIFS(Registro!$N:$N,Registro!$A:$A,E$3,Registro!$F:$F,$A10)) | F10: =IF(SUMIFS(Registro!$N:$N,Registro!$A:$A,F$3,Registro!$F:$F,$A10)=0,"",SUMIFS(Registro!$N:$N,Registro!$A:$A,F$3,Registro!$F:$F,$A10)) | G10: =IF(SUMIFS(Registro!$N:$N,Registro!$A:$A,G$3,Registro!$F:$F,$A10)=0,"",SUMIFS(Registro!$N:$N,Registro!$A:$A,G$3,Registro!$F:$F,$A10)) | H10: =IF(SUMIFS(Registro!$N:$N,Registro!$A:$A,H$3,Registro!$F:$F,$A10)=0,"",SUMIFS(Registro!$N:$N,Registro!$A:$A,H$3,Registro!$F:$F,$A10)) | I10: =IF(SUMIFS(Registro!$N:$N,Registro!$A:$A,I$3,Registro!$F:$F,$A10)=0,"",SUMIFS(Registro!$N:$N,Registro!$A:$A,I$3,Registro!$F:$F,$A10)) | ... AN10: =IF(SUMIFS(Registro!$N:$N,Registro!$A:$A,AN$3,Registro!$F:$F,$A10)=0,"",SUMIFS(Registro!$N:$N,Registro!$A:$A,AN$3,Registro!$F:$F,$A10))
A11: =Jugadores!$B$11 -> Jugador 7 | B11: =IF(SUMIFS(Registro!$N:$N,Registro!$A:$A,B$3,Registro!$F:$F,$A11)=0,"",SUMIFS(Registro!$N:$N,Registro!$A:$A,B$3,Registro!$F:$F,$A11)) | C11: =IF(SUMIFS(Registro!$N:$N,Registro!$A:$A,C$3,Registro!$F:$F,$A11)=0,"",SUMIFS(Registro!$N:$N,Registro!$A:$A,C$3,Registro!$F:$F,$A11)) | D11: =IF(SUMIFS(Registro!$N:$N,Registro!$A:$A,D$3,Registro!$F:$F,$A11)=0,"",SUMIFS(Registro!$N:$N,Registro!$A:$A,D$3,Registro!$F:$F,$A11)) | E11: =IF(SUMIFS(Registro!$N:$N,Registro!$A:$A,E$3,Registro!$F:$F,$A11)=0,"",SUMIFS(Registro!$N:$N,Registro!$A:$A,E$3,Registro!$F:$F,$A11)) | F11: =IF(SUMIFS(Registro!$N:$N,Registro!$A:$A,F$3,Registro!$F:$F,$A11)=0,"",SUMIFS(Registro!$N:$N,Registro!$A:$A,F$3,Registro!$F:$F,$A11)) | G11: =IF(SUMIFS(Registro!$N:$N,Registro!$A:$A,G$3,Registro!$F:$F,$A11)=0,"",SUMIFS(Registro!$N:$N,Registro!$A:$A,G$3,Registro!$F:$F,$A11)) | H11: =IF(SUMIFS(Registro!$N:$N,Registro!$A:$A,H$3,Registro!$F:$F,$A11)=0,"",SUMIFS(Registro!$N:$N,Registro!$A:$A,H$3,Registro!$F:$F,$A11)) | I11: =IF(SUMIFS(Registro!$N:$N,Registro!$A:$A,I$3,Registro!$F:$F,$A11)=0,"",SUMIFS(Registro!$N:$N,Registro!$A:$A,I$3,Registro!$F:$F,$A11)) | ... AN11: =IF(SUMIFS(Registro!$N:$N,Registro!$A:$A,AN$3,Registro!$F:$F,$A11)=0,"",SUMIFS(Registro!$N:$N,Registro!$A:$A,AN$3,Registro!$F:$F,$A11))
A12: =Jugadores!$B$12 -> Jugador 8 | B12: =IF(SUMIFS(Registro!$N:$N,Registro!$A:$A,B$3,Registro!$F:$F,$A12)=0,"",SUMIFS(Registro!$N:$N,Registro!$A:$A,B$3,Registro!$F:$F,$A12)) | C12: =IF(SUMIFS(Registro!$N:$N,Registro!$A:$A,C$3,Registro!$F:$F,$A12)=0,"",SUMIFS(Registro!$N:$N,Registro!$A:$A,C$3,Registro!$F:$F,$A12)) | D12: =IF(SUMIFS(Registro!$N:$N,Registro!$A:$A,D$3,Registro!$F:$F,$A12)=0,"",SUMIFS(Registro!$N:$N,Registro!$A:$A,D$3,Registro!$F:$F,$A12)) | E12: =IF(SUMIFS(Registro!$N:$N,Registro!$A:$A,E$3,Registro!$F:$F,$A12)=0,"",SUMIFS(Registro!$N:$N,Registro!$A:$A,E$3,Registro!$F:$F,$A12)) | F12: =IF(SUMIFS(Registro!$N:$N,Registro!$A:$A,F$3,Registro!$F:$F,$A12)=0,"",SUMIFS(Registro!$N:$N,Registro!$A:$A,F$3,Registro!$F:$F,$A12)) | G12: =IF(SUMIFS(Registro!$N:$N,Registro!$A:$A,G$3,Registro!$F:$F,$A12)=0,"",SUMIFS(Registro!$N:$N,Registro!$A:$A,G$3,Registro!$F:$F,$A12)) | H12: =IF(SUMIFS(Registro!$N:$N,Registro!$A:$A,H$3,Registro!$F:$F,$A12)=0,"",SUMIFS(Registro!$N:$N,Registro!$A:$A,H$3,Registro!$F:$F,$A12)) | I12: =IF(SUMIFS(Registro!$N:$N,Registro!$A:$A,I$3,Registro!$F:$F,$A12)=0,"",SUMIFS(Registro!$N:$N,Registro!$A:$A,I$3,Registro!$F:$F,$A12)) | ... AN12: =IF(SUMIFS(Registro!$N:$N,Registro!$A:$A,AN$3,Registro!$F:$F,$A12)=0,"",SUMIFS(Registro!$N:$N,Registro!$A:$A,AN$3,Registro!$F:$F,$A12))
A13: =Jugadores!$B$13 -> Jugador 9 | B13: =IF(SUMIFS(Registro!$N:$N,Registro!$A:$A,B$3,Registro!$F:$F,$A13)=0,"",SUMIFS(Registro!$N:$N,Registro!$A:$A,B$3,Registro!$F:$F,$A13)) | C13: =IF(SUMIFS(Registro!$N:$N,Registro!$A:$A,C$3,Registro!$F:$F,$A13)=0,"",SUMIFS(Registro!$N:$N,Registro!$A:$A,C$3,Registro!$F:$F,$A13)) | D13: =IF(SUMIFS(Registro!$N:$N,Registro!$A:$A,D$3,Registro!$F:$F,$A13)=0,"",SUMIFS(Registro!$N:$N,Registro!$A:$A,D$3,Registro!$F:$F,$A13)) | E13: =IF(SUMIFS(Registro!$N:$N,Registro!$A:$A,E$3,Registro!$F:$F,$A13)=0,"",SUMIFS(Registro!$N:$N,Registro!$A:$A,E$3,Registro!$F:$F,$A13)) | F13: =IF(SUMIFS(Registro!$N:$N,Registro!$A:$A,F$3,Registro!$F:$F,$A13)=0,"",SUMIFS(Registro!$N:$N,Registro!$A:$A,F$3,Registro!$F:$F,$A13)) | G13: =IF(SUMIFS(Registro!$N:$N,Registro!$A:$A,G$3,Registro!$F:$F,$A13)=0,"",SUMIFS(Registro!$N:$N,Registro!$A:$A,G$3,Registro!$F:$F,$A13)) | H13: =IF(SUMIFS(Registro!$N:$N,Registro!$A:$A,H$3,Registro!$F:$F,$A13)=0,"",SUMIFS(Registro!$N:$N,Registro!$A:$A,H$3,Registro!$F:$F,$A13)) | I13: =IF(SUMIFS(Registro!$N:$N,Registro!$A:$A,I$3,Registro!$F:$F,$A13)=0,"",SUMIFS(Registro!$N:$N,Registro!$A:$A,I$3,Registro!$F:$F,$A13)) | ... AN13: =IF(SUMIFS(Registro!$N:$N,Registro!$A:$A,AN$3,Registro!$F:$F,$A13)=0,"",SUMIFS(Registro!$N:$N,Registro!$A:$A,AN$3,Registro!$F:$F,$A13))
A14: =Jugadores!$B$14 -> Jugador 10 | B14: =IF(SUMIFS(Registro!$N:$N,Registro!$A:$A,B$3,Registro!$F:$F,$A14)=0,"",SUMIFS(Registro!$N:$N,Registro!$A:$A,B$3,Registro!$F:$F,$A14)) | C14: =IF(SUMIFS(Registro!$N:$N,Registro!$A:$A,C$3,Registro!$F:$F,$A14)=0,"",SUMIFS(Registro!$N:$N,Registro!$A:$A,C$3,Registro!$F:$F,$A14)) | D14: =IF(SUMIFS(Registro!$N:$N,Registro!$A:$A,D$3,Registro!$F:$F,$A14)=0,"",SUMIFS(Registro!$N:$N,Registro!$A:$A,D$3,Registro!$F:$F,$A14)) | E14: =IF(SUMIFS(Registro!$N:$N,Registro!$A:$A,E$3,Registro!$F:$F,$A14)=0,"",SUMIFS(Registro!$N:$N,Registro!$A:$A,E$3,Registro!$F:$F,$A14)) | F14: =IF(SUMIFS(Registro!$N:$N,Registro!$A:$A,F$3,Registro!$F:$F,$A14)=0,"",SUMIFS(Registro!$N:$N,Registro!$A:$A,F$3,Registro!$F:$F,$A14)) | G14: =IF(SUMIFS(Registro!$N:$N,Registro!$A:$A,G$3,Registro!$F:$F,$A14)=0,"",SUMIFS(Registro!$N:$N,Registro!$A:$A,G$3,Registro!$F:$F,$A14)) | H14: =IF(SUMIFS(Registro!$N:$N,Registro!$A:$A,H$3,Registro!$F:$F,$A14)=0,"",SUMIFS(Registro!$N:$N,Registro!$A:$A,H$3,Registro!$F:$F,$A14)) | I14: =IF(SUMIFS(Registro!$N:$N,Registro!$A:$A,I$3,Registro!$F:$F,$A14)=0,"",SUMIFS(Registro!$N:$N,Registro!$A:$A,I$3,Registro!$F:$F,$A14)) | ... AN14: =IF(SUMIFS(Registro!$N:$N,Registro!$A:$A,AN$3,Registro!$F:$F,$A14)=0,"",SUMIFS(Registro!$N:$N,Registro!$A:$A,AN$3,Registro!$F:$F,$A14))
A15: =Jugadores!$B$15 -> Jugador 11 | B15: =IF(SUMIFS(Registro!$N:$N,Registro!$A:$A,B$3,Registro!$F:$F,$A15)=0,"",SUMIFS(Registro!$N:$N,Registro!$A:$A,B$3,Registro!$F:$F,$A15)) | C15: =IF(SUMIFS(Registro!$N:$N,Registro!$A:$A,C$3,Registro!$F:$F,$A15)=0,"",SUMIFS(Registro!$N:$N,Registro!$A:$A,C$3,Registro!$F:$F,$A15)) | D15: =IF(SUMIFS(Registro!$N:$N,Registro!$A:$A,D$3,Registro!$F:$F,$A15)=0,"",SUMIFS(Registro!$N:$N,Registro!$A:$A,D$3,Registro!$F:$F,$A15)) | E15: =IF(SUMIFS(Registro!$N:$N,Registro!$A:$A,E$3,Registro!$F:$F,$A15)=0,"",SUMIFS(Registro!$N:$N,Registro!$A:$A,E$3,Registro!$F:$F,$A15)) | F15: =IF(SUMIFS(Registro!$N:$N,Registro!$A:$A,F$3,Registro!$F:$F,$A15)=0,"",SUMIFS(Registro!$N:$N,Registro!$A:$A,F$3,Registro!$F:$F,$A15)) | G15: =IF(SUMIFS(Registro!$N:$N,Registro!$A:$A,G$3,Registro!$F:$F,$A15)=0,"",SUMIFS(Registro!$N:$N,Registro!$A:$A,G$3,Registro!$F:$F,$A15)) | H15: =IF(SUMIFS(Registro!$N:$N,Registro!$A:$A,H$3,Registro!$F:$F,$A15)=0,"",SUMIFS(Registro!$N:$N,Registro!$A:$A,H$3,Registro!$F:$F,$A15)) | I15: =IF(SUMIFS(Registro!$N:$N,Registro!$A:$A,I$3,Registro!$F:$F,$A15)=0,"",SUMIFS(Registro!$N:$N,Registro!$A:$A,I$3,Registro!$F:$F,$A15)) | ... AN15: =IF(SUMIFS(Registro!$N:$N,Registro!$A:$A,AN$3,Registro!$F:$F,$A15)=0,"",SUMIFS(Registro!$N:$N,Registro!$A:$A,AN$3,Registro!$F:$F,$A15))
A16: =Jugadores!$B$16 -> Jugador 12 | B16: =IF(SUMIFS(Registro!$N:$N,Registro!$A:$A,B$3,Registro!$F:$F,$A16)=0,"",SUMIFS(Registro!$N:$N,Registro!$A:$A,B$3,Registro!$F:$F,$A16)) | C16: =IF(SUMIFS(Registro!$N:$N,Registro!$A:$A,C$3,Registro!$F:$F,$A16)=0,"",SUMIFS(Registro!$N:$N,Registro!$A:$A,C$3,Registro!$F:$F,$A16)) | D16: =IF(SUMIFS(Registro!$N:$N,Registro!$A:$A,D$3,Registro!$F:$F,$A16)=0,"",SUMIFS(Registro!$N:$N,Registro!$A:$A,D$3,Registro!$F:$F,$A16)) | E16: =IF(SUMIFS(Registro!$N:$N,Registro!$A:$A,E$3,Registro!$F:$F,$A16)=0,"",SUMIFS(Registro!$N:$N,Registro!$A:$A,E$3,Registro!$F:$F,$A16)) | F16: =IF(SUMIFS(Registro!$N:$N,Registro!$A:$A,F$3,Registro!$F:$F,$A16)=0,"",SUMIFS(Registro!$N:$N,Registro!$A:$A,F$3,Registro!$F:$F,$A16)) | G16: =IF(SUMIFS(Registro!$N:$N,Registro!$A:$A,G$3,Registro!$F:$F,$A16)=0,"",SUMIFS(Registro!$N:$N,Registro!$A:$A,G$3,Registro!$F:$F,$A16)) | H16: =IF(SUMIFS(Registro!$N:$N,Registro!$A:$A,H$3,Registro!$F:$F,$A16)=0,"",SUMIFS(Registro!$N:$N,Registro!$A:$A,H$3,Registro!$F:$F,$A16)) | I16: =IF(SUMIFS(Registro!$N:$N,Registro!$A:$A,I$3,Registro!$F:$F,$A16)=0,"",SUMIFS(Registro!$N:$N,Registro!$A:$A,I$3,Registro!$F:$F,$A16)) | ... AN16: =IF(SUMIFS(Registro!$N:$N,Registro!$A:$A,AN$3,Registro!$F:$F,$A16)=0,"",SUMIFS(Registro!$N:$N,Registro!$A:$A,AN$3,Registro!$F:$F,$A16))
A17: =Jugadores!$B$17 -> Jugador 13 | B17: =IF(SUMIFS(Registro!$N:$N,Registro!$A:$A,B$3,Registro!$F:$F,$A17)=0,"",SUMIFS(Registro!$N:$N,Registro!$A:$A,B$3,Registro!$F:$F,$A17)) | C17: =IF(SUMIFS(Registro!$N:$N,Registro!$A:$A,C$3,Registro!$F:$F,$A17)=0,"",SUMIFS(Registro!$N:$N,Registro!$A:$A,C$3,Registro!$F:$F,$A17)) | D17: =IF(SUMIFS(Registro!$N:$N,Registro!$A:$A,D$3,Registro!$F:$F,$A17)=0,"",SUMIFS(Registro!$N:$N,Registro!$A:$A,D$3,Registro!$F:$F,$A17)) | E17: =IF(SUMIFS(Registro!$N:$N,Registro!$A:$A,E$3,Registro!$F:$F,$A17)=0,"",SUMIFS(Registro!$N:$N,Registro!$A:$A,E$3,Registro!$F:$F,$A17)) | F17: =IF(SUMIFS(Registro!$N:$N,Registro!$A:$A,F$3,Registro!$F:$F,$A17)=0,"",SUMIFS(Registro!$N:$N,Registro!$A:$A,F$3,Registro!$F:$F,$A17)) | G17: =IF(SUMIFS(Registro!$N:$N,Registro!$A:$A,G$3,Registro!$F:$F,$A17)=0,"",SUMIFS(Registro!$N:$N,Registro!$A:$A,G$3,Registro!$F:$F,$A17)) | H17: =IF(SUMIFS(Registro!$N:$N,Registro!$A:$A,H$3,Registro!$F:$F,$A17)=0,"",SUMIFS(Registro!$N:$N,Registro!$A:$A,H$3,Registro!$F:$F,$A17)) | I17: =IF(SUMIFS(Registro!$N:$N,Registro!$A:$A,I$3,Registro!$F:$F,$A17)=0,"",SUMIFS(Registro!$N:$N,Registro!$A:$A,I$3,Registro!$F:$F,$A17)) | ... AN17: =IF(SUMIFS(Registro!$N:$N,Registro!$A:$A,AN$3,Registro!$F:$F,$A17)=0,"",SUMIFS(Registro!$N:$N,Registro!$A:$A,AN$3,Registro!$F:$F,$A17))
A18: =Jugadores!$B$18 -> Jugador 14 | B18: =IF(SUMIFS(Registro!$N:$N,Registro!$A:$A,B$3,Registro!$F:$F,$A18)=0,"",SUMIFS(Registro!$N:$N,Registro!$A:$A,B$3,Registro!$F:$F,$A18)) | C18: =IF(SUMIFS(Registro!$N:$N,Registro!$A:$A,C$3,Registro!$F:$F,$A18)=0,"",SUMIFS(Registro!$N:$N,Registro!$A:$A,C$3,Registro!$F:$F,$A18)) | D18: =IF(SUMIFS(Registro!$N:$N,Registro!$A:$A,D$3,Registro!$F:$F,$A18)=0,"",SUMIFS(Registro!$N:$N,Registro!$A:$A,D$3,Registro!$F:$F,$A18)) | E18: =IF(SUMIFS(Registro!$N:$N,Registro!$A:$A,E$3,Registro!$F:$F,$A18)=0,"",SUMIFS(Registro!$N:$N,Registro!$A:$A,E$3,Registro!$F:$F,$A18)) | F18: =IF(SUMIFS(Registro!$N:$N,Registro!$A:$A,F$3,Registro!$F:$F,$A18)=0,"",SUMIFS(Registro!$N:$N,Registro!$A:$A,F$3,Registro!$F:$F,$A18)) | G18: =IF(SUMIFS(Registro!$N:$N,Registro!$A:$A,G$3,Registro!$F:$F,$A18)=0,"",SUMIFS(Registro!$N:$N,Registro!$A:$A,G$3,Registro!$F:$F,$A18)) | H18: =IF(SUMIFS(Registro!$N:$N,Registro!$A:$A,H$3,Registro!$F:$F,$A18)=0,"",SUMIFS(Registro!$N:$N,Registro!$A:$A,H$3,Registro!$F:$F,$A18)) | I18: =IF(SUMIFS(Registro!$N:$N,Registro!$A:$A,I$3,Registro!$F:$F,$A18)=0,"",SUMIFS(Registro!$N:$N,Registro!$A:$A,I$3,Registro!$F:$F,$A18)) | ... AN18: =IF(SUMIFS(Registro!$N:$N,Registro!$A:$A,AN$3,Registro!$F:$F,$A18)=0,"",SUMIFS(Registro!$N:$N,Registro!$A:$A,AN$3,Registro!$F:$F,$A18))

Sheet Panel carga
A1: CARGA PERCIBIDA SEMANAL · RPE por duración de sesión
A2: Se rellena solo a partir de la hoja Registro.
A3: Semana | B3: 1 | C3: 2 | D3: 3 | E3: 4 | F3: 5 | G3: 6 | H3: 7 | I3: 8 | J3: 9 | K3: 10 | L3: 11 | M3: 12 | N3: 13 | O3: 14 | P3: 15 | Q3: 16 | R3: 17 | S3: 18 | T3: 19 | U3: 20 | V3: 21 | W3: 22 | X3: 23 | Y3: 24 | Z3: 25 | AA3: 26 | AB3: 27 | AC3: 28 | AD3: 29 | AE3: 30 | AF3: 31 | AG3: 32 | AH3: 33 | AI3: 34 | AJ3: 35 | AK3: 36 | AL3: 37 | AM3: 38 | AN3: 39
A4: Jugador | B4: M0 | C4: M0 | D4: M0 | E4: M0 | F4: M1 | G4: M1 | H4: M1 | I4: M1 | J4: M1 | K4: M1 | L4: M1 | M4: M1 | N4: M2 | O4: M2 | P4: M2 | Q4: M3 | R4: M3 | S4: M3 | T4: M3 | U4: M4 | V4: M4 | W4: M4 | X4: M4 | Y4: M4 | Z4: M4 | AA4: M5 | AB4: M5 | AC4: M6 | AD4: M6 | AE4: M6 | AF4: M7 | AG4: M7 | AH4: M7 | AI4: M8 | AJ4: M8 | AK4: M9 | AL4: M9 | AM4: M9 | AN4: M9
A5: =Jugadores!$B$5 -> Jugador 1 | B5: =IF(SUMIFS(Registro!$J:$J,Registro!$A:$A,B$3,Registro!$F:$F,$A5)=0,"",SUMIFS(Registro!$J:$J,Registro!$A:$A,B$3,Registro!$F:$F,$A5)) | C5: =IF(SUMIFS(Registro!$J:$J,Registro!$A:$A,C$3,Registro!$F:$F,$A5)=0,"",SUMIFS(Registro!$J:$J,Registro!$A:$A,C$3,Registro!$F:$F,$A5)) | D5: =IF(SUMIFS(Registro!$J:$J,Registro!$A:$A,D$3,Registro!$F:$F,$A5)=0,"",SUMIFS(Registro!$J:$J,Registro!$A:$A,D$3,Registro!$F:$F,$A5)) | E5: =IF(SUMIFS(Registro!$J:$J,Registro!$A:$A,E$3,Registro!$F:$F,$A5)=0,"",SUMIFS(Registro!$J:$J,Registro!$A:$A,E$3,Registro!$F:$F,$A5)) | F5: =IF(SUMIFS(Registro!$J:$J,Registro!$A:$A,F$3,Registro!$F:$F,$A5)=0,"",SUMIFS(Registro!$J:$J,Registro!$A:$A,F$3,Registro!$F:$F,$A5)) | G5: =IF(SUMIFS(Registro!$J:$J,Registro!$A:$A,G$3,Registro!$F:$F,$A5)=0,"",SUMIFS(Registro!$J:$J,Registro!$A:$A,G$3,Registro!$F:$F,$A5)) | H5: =IF(SUMIFS(Registro!$J:$J,Registro!$A:$A,H$3,Registro!$F:$F,$A5)=0,"",SUMIFS(Registro!$J:$J,Registro!$A:$A,H$3,Registro!$F:$F,$A5)) | I5: =IF(SUMIFS(Registro!$J:$J,Registro!$A:$A,I$3,Registro!$F:$F,$A5)=0,"",SUMIFS(Registro!$J:$J,Registro!$A:$A,I$3,Registro!$F:$F,$A5)) | ... AN5: =IF(SUMIFS(Registro!$J:$J,Registro!$A:$A,AN$3,Registro!$F:$F,$A5)=0,"",SUMIFS(Registro!$J:$J,Registro!$A:$A,AN$3,Registro!$F:$F,$A5))
A6: =Jugadores!$B$6 -> Jugador 2 | B6: =IF(SUMIFS(Registro!$J:$J,Registro!$A:$A,B$3,Registro!$F:$F,$A6)=0,"",SUMIFS(Registro!$J:$J,Registro!$A:$A,B$3,Registro!$F:$F,$A6)) | C6: =IF(SUMIFS(Registro!$J:$J,Registro!$A:$A,C$3,Registro!$F:$F,$A6)=0,"",SUMIFS(Registro!$J:$J,Registro!$A:$A,C$3,Registro!$F:$F,$A6)) | D6: =IF(SUMIFS(Registro!$J:$J,Registro!$A:$A,D$3,Registro!$F:$F,$A6)=0,"",SUMIFS(Registro!$J:$J,Registro!$A:$A,D$3,Registro!$F:$F,$A6)) | E6: =IF(SUMIFS(Registro!$J:$J,Registro!$A:$A,E$3,Registro!$F:$F,$A6)=0,"",SUMIFS(Registro!$J:$J,Registro!$A:$A,E$3,Registro!$F:$F,$A6)) | F6: =IF(SUMIFS(Registro!$J:$J,Registro!$A:$A,F$3,Registro!$F:$F,$A6)=0,"",SUMIFS(Registro!$J:$J,Registro!$A:$A,F$3,Registro!$F:$F,$A6)) | G6: =IF(SUMIFS(Registro!$J:$J,Registro!$A:$A,G$3,Registro!$F:$F,$A6)=0,"",SUMIFS(Registro!$J:$J,Registro!$A:$A,G$3,Registro!$F:$F,$A6)) | H6: =IF(SUMIFS(Registro!$J:$J,Registro!$A:$A,H$3,Registro!$F:$F,$A6)=0,"",SUMIFS(Registro!$J:$J,Registro!$A:$A,H$3,Registro!$F:$F,$A6)) | I6: =IF(SUMIFS(Registro!$J:$J,Registro!$A:$A,I$3,Registro!$F:$F,$A6)=0,"",SUMIFS(Registro!$J:$J,Registro!$A:$A,I$3,Registro!$F:$F,$A6)) | ... AN6: =IF(SUMIFS(Registro!$J:$J,Registro!$A:$A,AN$3,Registro!$F:$F,$A6)=0,"",SUMIFS(Registro!$J:$J,Registro!$A:$A,AN$3,Registro!$F:$F,$A6))
A7: =Jugadores!$B$7 -> Jugador 3 | B7: =IF(SUMIFS(Registro!$J:$J,Registro!$A:$A,B$3,Registro!$F:$F,$A7)=0,"",SUMIFS(Registro!$J:$J,Registro!$A:$A,B$3,Registro!$F:$F,$A7)) | C7: =IF(SUMIFS(Registro!$J:$J,Registro!$A:$A,C$3,Registro!$F:$F,$A7)=0,"",SUMIFS(Registro!$J:$J,Registro!$A:$A,C$3,Registro!$F:$F,$A7)) | D7: =IF(SUMIFS(Registro!$J:$J,Registro!$A:$A,D$3,Registro!$F:$F,$A7)=0,"",SUMIFS(Registro!$J:$J,Registro!$A:$A,D$3,Registro!$F:$F,$A7)) | E7: =IF(SUMIFS(Registro!$J:$J,Registro!$A:$A,E$3,Registro!$F:$F,$A7)=0,"",SUMIFS(Registro!$J:$J,Registro!$A:$A,E$3,Registro!$F:$F,$A7)) | F7: =IF(SUMIFS(Registro!$J:$J,Registro!$A:$A,F$3,Registro!$F:$F,$A7)=0,"",SUMIFS(Registro!$J:$J,Registro!$A:$A,F$3,Registro!$F:$F,$A7)) | G7: =IF(SUMIFS(Registro!$J:$J,Registro!$A:$A,G$3,Registro!$F:$F,$A7)=0,"",SUMIFS(Registro!$J:$J,Registro!$A:$A,G$3,Registro!$F:$F,$A7)) | H7: =IF(SUMIFS(Registro!$J:$J,Registro!$A:$A,H$3,Registro!$F:$F,$A7)=0,"",SUMIFS(Registro!$J:$J,Registro!$A:$A,H$3,Registro!$F:$F,$A7)) | I7: =IF(SUMIFS(Registro!$J:$J,Registro!$A:$A,I$3,Registro!$F:$F,$A7)=0,"",SUMIFS(Registro!$J:$J,Registro!$A:$A,I$3,Registro!$F:$F,$A7)) | ... AN7: =IF(SUMIFS(Registro!$J:$J,Registro!$A:$A,AN$3,Registro!$F:$F,$A7)=0,"",SUMIFS(Registro!$J:$J,Registro!$A:$A,AN$3,Registro!$F:$F,$A7))
A8: =Jugadores!$B$8 -> Jugador 4 | B8: =IF(SUMIFS(Registro!$J:$J,Registro!$A:$A,B$3,Registro!$F:$F,$A8)=0,"",SUMIFS(Registro!$J:$J,Registro!$A:$A,B$3,Registro!$F:$F,$A8)) | C8: =IF(SUMIFS(Registro!$J:$J,Registro!$A:$A,C$3,Registro!$F:$F,$A8)=0,"",SUMIFS(Registro!$J:$J,Registro!$A:$A,C$3,Registro!$F:$F,$A8)) | D8: =IF(SUMIFS(Registro!$J:$J,Registro!$A:$A,D$3,Registro!$F:$F,$A8)=0,"",SUMIFS(Registro!$J:$J,Registro!$A:$A,D$3,Registro!$F:$F,$A8)) | E8: =IF(SUMIFS(Registro!$J:$J,Registro!$A:$A,E$3,Registro!$F:$F,$A8)=0,"",SUMIFS(Registro!$J:$J,Registro!$A:$A,E$3,Registro!$F:$F,$A8)) | F8: =IF(SUMIFS(Registro!$J:$J,Registro!$A:$A,F$3,Registro!$F:$F,$A8)=0,"",SUMIFS(Registro!$J:$J,Registro!$A:$A,F$3,Registro!$F:$F,$A8)) | G8: =IF(SUMIFS(Registro!$J:$J,Registro!$A:$A,G$3,Registro!$F:$F,$A8)=0,"",SUMIFS(Registro!$J:$J,Registro!$A:$A,G$3,Registro!$F:$F,$A8)) | H8: =IF(SUMIFS(Registro!$J:$J,Registro!$A:$A,H$3,Registro!$F:$F,$A8)=0,"",SUMIFS(Registro!$J:$J,Registro!$A:$A,H$3,Registro!$F:$F,$A8)) | I8: =IF(SUMIFS(Registro!$J:$J,Registro!$A:$A,I$3,Registro!$F:$F,$A8)=0,"",SUMIFS(Registro!$J:$J,Registro!$A:$A,I$3,Registro!$F:$F,$A8)) | ... AN8: =IF(SUMIFS(Registro!$J:$J,Registro!$A:$A,AN$3,Registro!$F:$F,$A8)=0,"",SUMIFS(Registro!$J:$J,Registro!$A:$A,AN$3,Registro!$F:$F,$A8))
A9: =Jugadores!$B$9 -> Jugador 5 | B9: =IF(SUMIFS(Registro!$J:$J,Registro!$A:$A,B$3,Registro!$F:$F,$A9)=0,"",SUMIFS(Registro!$J:$J,Registro!$A:$A,B$3,Registro!$F:$F,$A9)) | C9: =IF(SUMIFS(Registro!$J:$J,Registro!$A:$A,C$3,Registro!$F:$F,$A9)=0,"",SUMIFS(Registro!$J:$J,Registro!$A:$A,C$3,Registro!$F:$F,$A9)) | D9: =IF(SUMIFS(Registro!$J:$J,Registro!$A:$A,D$3,Registro!$F:$F,$A9)=0,"",SUMIFS(Registro!$J:$J,Registro!$A:$A,D$3,Registro!$F:$F,$A9)) | E9: =IF(SUMIFS(Registro!$J:$J,Registro!$A:$A,E$3,Registro!$F:$F,$A9)=0,"",SUMIFS(Registro!$J:$J,Registro!$A:$A,E$3,Registro!$F:$F,$A9)) | F9: =IF(SUMIFS(Registro!$J:$J,Registro!$A:$A,F$3,Registro!$F:$F,$A9)=0,"",SUMIFS(Registro!$J:$J,Registro!$A:$A,F$3,Registro!$F:$F,$A9)) | G9: =IF(SUMIFS(Registro!$J:$J,Registro!$A:$A,G$3,Registro!$F:$F,$A9)=0,"",SUMIFS(Registro!$J:$J,Registro!$A:$A,G$3,Registro!$F:$F,$A9)) | H9: =IF(SUMIFS(Registro!$J:$J,Registro!$A:$A,H$3,Registro!$F:$F,$A9)=0,"",SUMIFS(Registro!$J:$J,Registro!$A:$A,H$3,Registro!$F:$F,$A9)) | I9: =IF(SUMIFS(Registro!$J:$J,Registro!$A:$A,I$3,Registro!$F:$F,$A9)=0,"",SUMIFS(Registro!$J:$J,Registro!$A:$A,I$3,Registro!$F:$F,$A9)) | ... AN9: =IF(SUMIFS(Registro!$J:$J,Registro!$A:$A,AN$3,Registro!$F:$F,$A9)=0,"",SUMIFS(Registro!$J:$J,Registro!$A:$A,AN$3,Registro!$F:$F,$A9))
A10: =Jugadores!$B$10 -> Jugador 6 | B10: =IF(SUMIFS(Registro!$J:$J,Registro!$A:$A,B$3,Registro!$F:$F,$A10)=0,"",SUMIFS(Registro!$J:$J,Registro!$A:$A,B$3,Registro!$F:$F,$A10)) | C10: =IF(SUMIFS(Registro!$J:$J,Registro!$A:$A,C$3,Registro!$F:$F,$A10)=0,"",SUMIFS(Registro!$J:$J,Registro!$A:$A,C$3,Registro!$F:$F,$A10)) | D10: =IF(SUMIFS(Registro!$J:$J,Registro!$A:$A,D$3,Registro!$F:$F,$A10)=0,"",SUMIFS(Registro!$J:$J,Registro!$A:$A,D$3,Registro!$F:$F,$A10)) | E10: =IF(SUMIFS(Registro!$J:$J,Registro!$A:$A,E$3,Registro!$F:$F,$A10)=0,"",SUMIFS(Registro!$J:$J,Registro!$A:$A,E$3,Registro!$F:$F,$A10)) | F10: =IF(SUMIFS(Registro!$J:$J,Registro!$A:$A,F$3,Registro!$F:$F,$A10)=0,"",SUMIFS(Registro!$J:$J,Registro!$A:$A,F$3,Registro!$F:$F,$A10)) | G10: =IF(SUMIFS(Registro!$J:$J,Registro!$A:$A,G$3,Registro!$F:$F,$A10)=0,"",SUMIFS(Registro!$J:$J,Registro!$A:$A,G$3,Registro!$F:$F,$A10)) | H10: =IF(SUMIFS(Registro!$J:$J,Registro!$A:$A,H$3,Registro!$F:$F,$A10)=0,"",SUMIFS(Registro!$J:$J,Registro!$A:$A,H$3,Registro!$F:$F,$A10)) | I10: =IF(SUMIFS(Registro!$J:$J,Registro!$A:$A,I$3,Registro!$F:$F,$A10)=0,"",SUMIFS(Registro!$J:$J,Registro!$A:$A,I$3,Registro!$F:$F,$A10)) | ... AN10: =IF(SUMIFS(Registro!$J:$J,Registro!$A:$A,AN$3,Registro!$F:$F,$A10)=0,"",SUMIFS(Registro!$J:$J,Registro!$A:$A,AN$3,Registro!$F:$F,$A10))
A11: =Jugadores!$B$11 -> Jugador 7 | B11: =IF(SUMIFS(Registro!$J:$J,Registro!$A:$A,B$3,Registro!$F:$F,$A11)=0,"",SUMIFS(Registro!$J:$J,Registro!$A:$A,B$3,Registro!$F:$F,$A11)) | C11: =IF(SUMIFS(Registro!$J:$J,Registro!$A:$A,C$3,Registro!$F:$F,$A11)=0,"",SUMIFS(Registro!$J:$J,Registro!$A:$A,C$3,Registro!$F:$F,$A11)) | D11: =IF(SUMIFS(Registro!$J:$J,Registro!$A:$A,D$3,Registro!$F:$F,$A11)=0,"",SUMIFS(Registro!$J:$J,Registro!$A:$A,D$3,Registro!$F:$F,$A11)) | E11: =IF(SUMIFS(Registro!$J:$J,Registro!$A:$A,E$3,Registro!$F:$F,$A11)=0,"",SUMIFS(Registro!$J:$J,Registro!$A:$A,E$3,Registro!$F:$F,$A11)) | F11: =IF(SUMIFS(Registro!$J:$J,Registro!$A:$A,F$3,Registro!$F:$F,$A11)=0,"",SUMIFS(Registro!$J:$J,Registro!$A:$A,F$3,Registro!$F:$F,$A11)) | G11: =IF(SUMIFS(Registro!$J:$J,Registro!$A:$A,G$3,Registro!$F:$F,$A11)=0,"",SUMIFS(Registro!$J:$J,Registro!$A:$A,G$3,Registro!$F:$F,$A11)) | H11: =IF(SUMIFS(Registro!$J:$J,Registro!$A:$A,H$3,Registro!$F:$F,$A11)=0,"",SUMIFS(Registro!$J:$J,Registro!$A:$A,H$3,Registro!$F:$F,$A11)) | I11: =IF(SUMIFS(Registro!$J:$J,Registro!$A:$A,I$3,Registro!$F:$F,$A11)=0,"",SUMIFS(Registro!$J:$J,Registro!$A:$A,I$3,Registro!$F:$F,$A11)) | ... AN11: =IF(SUMIFS(Registro!$J:$J,Registro!$A:$A,AN$3,Registro!$F:$F,$A11)=0,"",SUMIFS(Registro!$J:$J,Registro!$A:$A,AN$3,Registro!$F:$F,$A11))
A12: =Jugadores!$B$12 -> Jugador 8 | B12: =IF(SUMIFS(Registro!$J:$J,Registro!$A:$A,B$3,Registro!$F:$F,$A12)=0,"",SUMIFS(Registro!$J:$J,Registro!$A:$A,B$3,Registro!$F:$F,$A12)) | C12: =IF(SUMIFS(Registro!$J:$J,Registro!$A:$A,C$3,Registro!$F:$F,$A12)=0,"",SUMIFS(Registro!$J:$J,Registro!$A:$A,C$3,Registro!$F:$F,$A12)) | D12: =IF(SUMIFS(Registro!$J:$J,Registro!$A:$A,D$3,Registro!$F:$F,$A12)=0,"",SUMIFS(Registro!$J:$J,Registro!$A:$A,D$3,Registro!$F:$F,$A12)) | E12: =IF(SUMIFS(Registro!$J:$J,Registro!$A:$A,E$3,Registro!$F:$F,$A12)=0,"",SUMIFS(Registro!$J:$J,Registro!$A:$A,E$3,Registro!$F:$F,$A12)) | F12: =IF(SUMIFS(Registro!$J:$J,Registro!$A:$A,F$3,Registro!$F:$F,$A12)=0,"",SUMIFS(Registro!$J:$J,Registro!$A:$A,F$3,Registro!$F:$F,$A12)) | G12: =IF(SUMIFS(Registro!$J:$J,Registro!$A:$A,G$3,Registro!$F:$F,$A12)=0,"",SUMIFS(Registro!$J:$J,Registro!$A:$A,G$3,Registro!$F:$F,$A12)) | H12: =IF(SUMIFS(Registro!$J:$J,Registro!$A:$A,H$3,Registro!$F:$F,$A12)=0,"",SUMIFS(Registro!$J:$J,Registro!$A:$A,H$3,Registro!$F:$F,$A12)) | I12: =IF(SUMIFS(Registro!$J:$J,Registro!$A:$A,I$3,Registro!$F:$F,$A12)=0,"",SUMIFS(Registro!$J:$J,Registro!$A:$A,I$3,Registro!$F:$F,$A12)) | ... AN12: =IF(SUMIFS(Registro!$J:$J,Registro!$A:$A,AN$3,Registro!$F:$F,$A12)=0,"",SUMIFS(Registro!$J:$J,Registro!$A:$A,AN$3,Registro!$F:$F,$A12))
A13: =Jugadores!$B$13 -> Jugador 9 | B13: =IF(SUMIFS(Registro!$J:$J,Registro!$A:$A,B$3,Registro!$F:$F,$A13)=0,"",SUMIFS(Registro!$J:$J,Registro!$A:$A,B$3,Registro!$F:$F,$A13)) | C13: =IF(SUMIFS(Registro!$J:$J,Registro!$A:$A,C$3,Registro!$F:$F,$A13)=0,"",SUMIFS(Registro!$J:$J,Registro!$A:$A,C$3,Registro!$F:$F,$A13)) | D13: =IF(SUMIFS(Registro!$J:$J,Registro!$A:$A,D$3,Registro!$F:$F,$A13)=0,"",SUMIFS(Registro!$J:$J,Registro!$A:$A,D$3,Registro!$F:$F,$A13)) | E13: =IF(SUMIFS(Registro!$J:$J,Registro!$A:$A,E$3,Registro!$F:$F,$A13)=0,"",SUMIFS(Registro!$J:$J,Registro!$A:$A,E$3,Registro!$F:$F,$A13)) | F13: =IF(SUMIFS(Registro!$J:$J,Registro!$A:$A,F$3,Registro!$F:$F,$A13)=0,"",SUMIFS(Registro!$J:$J,Registro!$A:$A,F$3,Registro!$F:$F,$A13)) | G13: =IF(SUMIFS(Registro!$J:$J,Registro!$A:$A,G$3,Registro!$F:$F,$A13)=0,"",SUMIFS(Registro!$J:$J,Registro!$A:$A,G$3,Registro!$F:$F,$A13)) | H13: =IF(SUMIFS(Registro!$J:$J,Registro!$A:$A,H$3,Registro!$F:$F,$A13)=0,"",SUMIFS(Registro!$J:$J,Registro!$A:$A,H$3,Registro!$F:$F,$A13)) | I13: =IF(SUMIFS(Registro!$J:$J,Registro!$A:$A,I$3,Registro!$F:$F,$A13)=0,"",SUMIFS(Registro!$J:$J,Registro!$A:$A,I$3,Registro!$F:$F,$A13)) | ... AN13: =IF(SUMIFS(Registro!$J:$J,Registro!$A:$A,AN$3,Registro!$F:$F,$A13)=0,"",SUMIFS(Registro!$J:$J,Registro!$A:$A,AN$3,Registro!$F:$F,$A13))
A14: =Jugadores!$B$14 -> Jugador 10 | B14: =IF(SUMIFS(Registro!$J:$J,Registro!$A:$A,B$3,Registro!$F:$F,$A14)=0,"",SUMIFS(Registro!$J:$J,Registro!$A:$A,B$3,Registro!$F:$F,$A14)) | C14: =IF(SUMIFS(Registro!$J:$J,Registro!$A:$A,C$3,Registro!$F:$F,$A14)=0,"",SUMIFS(Registro!$J:$J,Registro!$A:$A,C$3,Registro!$F:$F,$A14)) | D14: =IF(SUMIFS(Registro!$J:$J,Registro!$A:$A,D$3,Registro!$F:$F,$A14)=0,"",SUMIFS(Registro!$J:$J,Registro!$A:$A,D$3,Registro!$F:$F,$A14)) | E14: =IF(SUMIFS(Registro!$J:$J,Registro!$A:$A,E$3,Registro!$F:$F,$A14)=0,"",SUMIFS(Registro!$J:$J,Registro!$A:$A,E$3,Registro!$F:$F,$A14)) | F14: =IF(SUMIFS(Registro!$J:$J,Registro!$A:$A,F$3,Registro!$F:$F,$A14)=0,"",SUMIFS(Registro!$J:$J,Registro!$A:$A,F$3,Registro!$F:$F,$A14)) | G14: =IF(SUMIFS(Registro!$J:$J,Registro!$A:$A,G$3,Registro!$F:$F,$A14)=0,"",SUMIFS(Registro!$J:$J,Registro!$A:$A,G$3,Registro!$F:$F,$A14)) | H14: =IF(SUMIFS(Registro!$J:$J,Registro!$A:$A,H$3,Registro!$F:$F,$A14)=0,"",SUMIFS(Registro!$J:$J,Registro!$A:$A,H$3,Registro!$F:$F,$A14)) | I14: =IF(SUMIFS(Registro!$J:$J,Registro!$A:$A,I$3,Registro!$F:$F,$A14)=0,"",SUMIFS(Registro!$J:$J,Registro!$A:$A,I$3,Registro!$F:$F,$A14)) | ... AN14: =IF(SUMIFS(Registro!$J:$J,Registro!$A:$A,AN$3,Registro!$F:$F,$A14)=0,"",SUMIFS(Registro!$J:$J,Registro!$A:$A,AN$3,Registro!$F:$F,$A14))
A15: =Jugadores!$B$15 -> Jugador 11 | B15: =IF(SUMIFS(Registro!$J:$J,Registro!$A:$A,B$3,Registro!$F:$F,$A15)=0,"",SUMIFS(Registro!$J:$J,Registro!$A:$A,B$3,Registro!$F:$F,$A15)) | C15: =IF(SUMIFS(Registro!$J:$J,Registro!$A:$A,C$3,Registro!$F:$F,$A15)=0,"",SUMIFS(Registro!$J:$J,Registro!$A:$A,C$3,Registro!$F:$F,$A15)) | D15: =IF(SUMIFS(Registro!$J:$J,Registro!$A:$A,D$3,Registro!$F:$F,$A15)=0,"",SUMIFS(Registro!$J:$J,Registro!$A:$A,D$3,Registro!$F:$F,$A15)) | E15: =IF(SUMIFS(Registro!$J:$J,Registro!$A:$A,E$3,Registro!$F:$F,$A15)=0,"",SUMIFS(Registro!$J:$J,Registro!$A:$A,E$3,Registro!$F:$F,$A15)) | F15: =IF(SUMIFS(Registro!$J:$J,Registro!$A:$A,F$3,Registro!$F:$F,$A15)=0,"",SUMIFS(Registro!$J:$J,Registro!$A:$A,F$3,Registro!$F:$F,$A15)) | G15: =IF(SUMIFS(Registro!$J:$J,Registro!$A:$A,G$3,Registro!$F:$F,$A15)=0,"",SUMIFS(Registro!$J:$J,Registro!$A:$A,G$3,Registro!$F:$F,$A15)) | H15: =IF(SUMIFS(Registro!$J:$J,Registro!$A:$A,H$3,Registro!$F:$F,$A15)=0,"",SUMIFS(Registro!$J:$J,Registro!$A:$A,H$3,Registro!$F:$F,$A15)) | I15: =IF(SUMIFS(Registro!$J:$J,Registro!$A:$A,I$3,Registro!$F:$F,$A15)=0,"",SUMIFS(Registro!$J:$J,Registro!$A:$A,I$3,Registro!$F:$F,$A15)) | ... AN15: =IF(SUMIFS(Registro!$J:$J,Registro!$A:$A,AN$3,Registro!$F:$F,$A15)=0,"",SUMIFS(Registro!$J:$J,Registro!$A:$A,AN$3,Registro!$F:$F,$A15))
A16: =Jugadores!$B$16 -> Jugador 12 | B16: =IF(SUMIFS(Registro!$J:$J,Registro!$A:$A,B$3,Registro!$F:$F,$A16)=0,"",SUMIFS(Registro!$J:$J,Registro!$A:$A,B$3,Registro!$F:$F,$A16)) | C16: =IF(SUMIFS(Registro!$J:$J,Registro!$A:$A,C$3,Registro!$F:$F,$A16)=0,"",SUMIFS(Registro!$J:$J,Registro!$A:$A,C$3,Registro!$F:$F,$A16)) | D16: =IF(SUMIFS(Registro!$J:$J,Registro!$A:$A,D$3,Registro!$F:$F,$A16)=0,"",SUMIFS(Registro!$J:$J,Registro!$A:$A,D$3,Registro!$F:$F,$A16)) | E16: =IF(SUMIFS(Registro!$J:$J,Registro!$A:$A,E$3,Registro!$F:$F,$A16)=0,"",SUMIFS(Registro!$J:$J,Registro!$A:$A,E$3,Registro!$F:$F,$A16)) | F16: =IF(SUMIFS(Registro!$J:$J,Registro!$A:$A,F$3,Registro!$F:$F,$A16)=0,"",SUMIFS(Registro!$J:$J,Registro!$A:$A,F$3,Registro!$F:$F,$A16)) | G16: =IF(SUMIFS(Registro!$J:$J,Registro!$A:$A,G$3,Registro!$F:$F,$A16)=0,"",SUMIFS(Registro!$J:$J,Registro!$A:$A,G$3,Registro!$F:$F,$A16)) | H16: =IF(SUMIFS(Registro!$J:$J,Registro!$A:$A,H$3,Registro!$F:$F,$A16)=0,"",SUMIFS(Registro!$J:$J,Registro!$A:$A,H$3,Registro!$F:$F,$A16)) | I16: =IF(SUMIFS(Registro!$J:$J,Registro!$A:$A,I$3,Registro!$F:$F,$A16)=0,"",SUMIFS(Registro!$J:$J,Registro!$A:$A,I$3,Registro!$F:$F,$A16)) | ... AN16: =IF(SUMIFS(Registro!$J:$J,Registro!$A:$A,AN$3,Registro!$F:$F,$A16)=0,"",SUMIFS(Registro!$J:$J,Registro!$A:$A,AN$3,Registro!$F:$F,$A16))
A17: =Jugadores!$B$17 -> Jugador 13 | B17: =IF(SUMIFS(Registro!$J:$J,Registro!$A:$A,B$3,Registro!$F:$F,$A17)=0,"",SUMIFS(Registro!$J:$J,Registro!$A:$A,B$3,Registro!$F:$F,$A17)) | C17: =IF(SUMIFS(Registro!$J:$J,Registro!$A:$A,C$3,Registro!$F:$F,$A17)=0,"",SUMIFS(Registro!$J:$J,Registro!$A:$A,C$3,Registro!$F:$F,$A17)) | D17: =IF(SUMIFS(Registro!$J:$J,Registro!$A:$A,D$3,Registro!$F:$F,$A17)=0,"",SUMIFS(Registro!$J:$J,Registro!$A:$A,D$3,Registro!$F:$F,$A17)) | E17: =IF(SUMIFS(Registro!$J:$J,Registro!$A:$A,E$3,Registro!$F:$F,$A17)=0,"",SUMIFS(Registro!$J:$J,Registro!$A:$A,E$3,Registro!$F:$F,$A17)) | F17: =IF(SUMIFS(Registro!$J:$J,Registro!$A:$A,F$3,Registro!$F:$F,$A17)=0,"",SUMIFS(Registro!$J:$J,Registro!$A:$A,F$3,Registro!$F:$F,$A17)) | G17: =IF(SUMIFS(Registro!$J:$J,Registro!$A:$A,G$3,Registro!$F:$F,$A17)=0,"",SUMIFS(Registro!$J:$J,Registro!$A:$A,G$3,Registro!$F:$F,$A17)) | H17: =IF(SUMIFS(Registro!$J:$J,Registro!$A:$A,H$3,Registro!$F:$F,$A17)=0,"",SUMIFS(Registro!$J:$J,Registro!$A:$A,H$3,Registro!$F:$F,$A17)) | I17: =IF(SUMIFS(Registro!$J:$J,Registro!$A:$A,I$3,Registro!$F:$F,$A17)=0,"",SUMIFS(Registro!$J:$J,Registro!$A:$A,I$3,Registro!$F:$F,$A17)) | ... AN17: =IF(SUMIFS(Registro!$J:$J,Registro!$A:$A,AN$3,Registro!$F:$F,$A17)=0,"",SUMIFS(Registro!$J:$J,Registro!$A:$A,AN$3,Registro!$F:$F,$A17))
A18: =Jugadores!$B$18 -> Jugador 14 | B18: =IF(SUMIFS(Registro!$J:$J,Registro!$A:$A,B$3,Registro!$F:$F,$A18)=0,"",SUMIFS(Registro!$J:$J,Registro!$A:$A,B$3,Registro!$F:$F,$A18)) | C18: =IF(SUMIFS(Registro!$J:$J,Registro!$A:$A,C$3,Registro!$F:$F,$A18)=0,"",SUMIFS(Registro!$J:$J,Registro!$A:$A,C$3,Registro!$F:$F,$A18)) | D18: =IF(SUMIFS(Registro!$J:$J,Registro!$A:$A,D$3,Registro!$F:$F,$A18)=0,"",SUMIFS(Registro!$J:$J,Registro!$A:$A,D$3,Registro!$F:$F,$A18)) | E18: =IF(SUMIFS(Registro!$J:$J,Registro!$A:$A,E$3,Registro!$F:$F,$A18)=0,"",SUMIFS(Registro!$J:$J,Registro!$A:$A,E$3,Registro!$F:$F,$A18)) | F18: =IF(SUMIFS(Registro!$J:$J,Registro!$A:$A,F$3,Registro!$F:$F,$A18)=0,"",SUMIFS(Registro!$J:$J,Registro!$A:$A,F$3,Registro!$F:$F,$A18)) | G18: =IF(SUMIFS(Registro!$J:$J,Registro!$A:$A,G$3,Registro!$F:$F,$A18)=0,"",SUMIFS(Registro!$J:$J,Registro!$A:$A,G$3,Registro!$F:$F,$A18)) | H18: =IF(SUMIFS(Registro!$J:$J,Registro!$A:$A,H$3,Registro!$F:$F,$A18)=0,"",SUMIFS(Registro!$J:$J,Registro!$A:$A,H$3,Registro!$F:$F,$A18)) | I18: =IF(SUMIFS(Registro!$J:$J,Registro!$A:$A,I$3,Registro!$F:$F,$A18)=0,"",SUMIFS(Registro!$J:$J,Registro!$A:$A,I$3,Registro!$F:$F,$A18)) | ... AN18: =IF(SUMIFS(Registro!$J:$J,Registro!$A:$A,AN$3,Registro!$F:$F,$A18)=0,"",SUMIFS(Registro!$J:$J,Registro!$A:$A,AN$3,Registro!$F:$F,$A18))
A20: Carga planificada | B20: 6 | C20: 8 | D20: 9 | E20: 6 | F20: 10 | G20: 8 | H20: 9 | I20: 10 | J20: 7 | K20: 9 | L20: 9 | M20: 6 | N20: 9 | O20: 7 | P20: 6 | Q20: 5 | R20: 3 | S20: 5 | T20: 6 | U20: 5 | V20: 5 | W20: 6 | X20: 4 | Y20: 6 | Z20: 4 | AA20: 5 | AB20: 4 | AC20: 10 | AD20: 5 | AE20: 7 | AF20: 6 | AG20: 5 | AH20: 5 | AI20: 6 | AJ20: 4 | AK20: 4 | AL20: 4 | AM20: 3 | AN20: 3
